<?xml version="1.0" encoding="utf-8"?>
<robot name="car" xmlns:xacro="http://ros.org/wiki/xacro">



    <link name="base_link">

        <visual>
          <origin rpy="0 0 0" xyz="0 0 0.03"/>
          <geometry>
            <box size="0.386 0.236 0.06" />
          </geometry>
        </visual>

        <inertial>
          <origin rpy="0 0 0" xyz="0 0 0.03"/>
          <mass value="6.1"/>
          <inertia ixx="0.0425" ixy="0.0" ixz="0.0" iyy="0.1136" iyz="0.0" izz="0.1561" />
        </inertial>

        <collision>
          <origin rpy="0 0 0" xyz="0 0 0.03" />
          <geometry>
            <box size="0.386 0.236 0.06"/>
          </geometry>
        </collision>

    </link>

    <link name="laser_link">
        <visual>
          <origin rpy="0 0 0" xyz="0 0 0"/>
          <geometry>
            <cylinder length="0.051" radius="0.028"/>
          </geometry>
        </visual>
    </link>

    <link name="USB_camera_link">
        <visual>
          <origin rpy="0 0 0" xyz="0 0 0"/>
          <geometry>
            <box size="0.02 0.02 0.02"/>
          </geometry>
        </visual>

        <inertial>
          <origin rpy="0 0 0" xyz="0 0 0"/>
          <mass value="0.01"/>
          <inertia ixx="1e-6" ixy="1e-6" ixz="1e-6" iyy="1e-6" iyz="1e-6" izz="1e-6" />
        </inertial>
    </link>

    <joint name="base_laser_joint" type="fixed">
        <origin xyz="0.1 0 0.085" rpy="0 0 0" />
        <parent link="base_link"/>
        <child link="laser_link" />
    </joint>

    <joint name="base_USBcamera_joint" type="continuous">
        <origin xyz="0.203 0 0.07" rpy="0 0 0" />
        <axis xyz="0 1 0"/>
        <parent link="base_link"/>
        <child link="USB_camera_link" />
        <limit effort="2.0" lower="-1.8" upper="1.8" velocity="0.5"/>
        <dynamics damping="1.0" friction="1.0"/>
    </joint>

    <ros2_control name="GazeboSystem" type="system">
        <hardware>
          <plugin>gazebo_ros2_control/GazeboSystem</plugin>
        </hardware>
        <joint name="base_USBcamera_joint">
          <command_interface name="position">
            <param name="min">-2</param>
            <param name="max">2</param>
          </command_interface>
          <state_interface name="position"/>
          <state_interface name="velocity"/>
          <state_interface name="effort"/>
        </joint>
    </ros2_control>

    <gazebo reference="base_link">
        <material>Gazebo/Purple</material>
    </gazebo>

    <gazebo reference="laser_link">
        <material>Gazebo/Black</material>
    </gazebo>

    <gazebo reference="USB_camera_link">
        <material>Gazebo/Red</material>
    </gazebo>

    <gazebo>
        <plugin name='planar_move' filename='libgazebo_ros_planar_move.so'>
            <ros>
              <namespace>/car</namespace>
            </ros>

            <update_rate>100</update_rate>
            <publish_rate>10</publish_rate>

            <!-- output -->
            <publish_odom>true</publish_odom>
            <publish_odom_tf>true</publish_odom_tf>

            <odometry_frame>odom_link</odometry_frame>
            <robot_base_frame>base_link</robot_base_frame>

            <covariance_x>0.0001</covariance_x>
            <covariance_y>0.0001</covariance_y>
            <covariance_yaw>0.01</covariance_yaw>
        </plugin>
    </gazebo>

    <gazebo reference="laser_link">
        <sensor name="sensor_ray" type="ray">
          <ray>
            <scan>
              <horizontal>
                <samples>1000</samples>
                <resolution>1.0</resolution>
                <min_angle>-1.5</min_angle>
                <max_angle>1.5</max_angle>
              </horizontal>
            </scan>
            <range>
              <min>0.1</min>
              <max>10</max>
            </range>
            <noise>
              <type>gaussian</type>
              <!-- Noise parameters based on published spec for Hokuyo laser
                    achieving "+-30mm" accuracy at range < 10m.  A mean of 0.0m and
                    stddev of 0.01m will put 99.7% of samples within 0.03m of the true
                    reading. -->
              <mean>0.0</mean>
              <stddev>0.01</stddev>
            </noise>
          </ray>
          <always_on>true</always_on>
          <update_rate>10.0</update_rate>
          <plugin name="laserscan" filename="libgazebo_ros_ray_sensor.so">
            <ros>
              <namespace>/ray</namespace>
              <remapping>~/out:=laserscan</remapping>
            </ros>
            <output_type>sensor_msgs/LaserScan</output_type>
          </plugin>
          <plugin name="range" filename="libgazebo_ros_ray_sensor.so">
            <ros>
              <namespace>/ray</namespace>
              <remapping>~/out:=range</remapping>
            </ros>
            <output_type>sensor_msgs/Range</output_type>
          </plugin>
        </sensor>
    </gazebo>

    <gazebo reference="USB_camera_link">
    <sensor name="camera_sensor" type="camera">
      <update_rate>30.0</update_rate>
      <always_on>1</always_on>
      <camera name="camera">
        <horizontal_fov>1.3962634</horizontal_fov>
        <image>
          <width>800</width>
          <height>800</height>
          <format>R8G8B8</format>
        </image>
        <clip>
          <near>0.01</near>
          <far>40</far>
        </clip>
        <distortion>
          <k1>0.0</k1>
          <k2>0.0</k2>
          <k3>0.0</k3>
          <p1>0.0</p1>
          <p2>0.0</p2>
          <center>0.5 0.5</center>
        </distortion>
      </camera>
      <plugin filename="libgazebo_ros_camera.so" name="camera_controller">
        <ros>
          <namespace>/car</namespace>
          <argument>camera/image_raw:=/camera/image</argument>
          <argument>camera/camera_info:=/camera/image/camera_info</argument>
        </ros>
        <camera_name>camera_car_front</camera_name>
        <frame_name>camera_link</frame_name>
        <hack_baseline>0.07</hack_baseline>
      </plugin>
    </sensor>
  </gazebo>

    <gazebo>
        <plugin filename="libgazebo_ros2_control.so" name="gazebo_ros2_control_camera">
          <parameters>/home/demons/dev_ws/install/npu_sim/share/npu_sim/config/joint_controller.yaml</parameters>
        </plugin>
    </gazebo>

</robot>
